Workbook

Sheet CO-PO Mapping
A1: DEPARTMENT OF COMPUTER SCIENCE
A2: CO to PO & PSO Mapping
A3: II Year III Semester
A4: SUBJECT: Advanced Engineering Mathematics Faculty: Dr. Kalpana Fatawat
A5: Course Outcome | B5: PO1 | C5: PO2 | D5: PO3 | E5: PO4 | F5: PO5 | G5: PO6 | H5: PO7 | I5: PO8 | J5: PO9 | K5: PO10 | L5: PO11 | M5: PO12 | N5: PSO1 | O5: PSO2 | P5: PSO3
A6: CO23CS201.1 | B6: 2 | C6: 2 | D6: 0 | E6: 1 | F6: 1 | G6: 0 | H6: 0 | I6: 0 | J6: 0 | K6: 0 | L6: 0 | M6: 1 | N6: 0 | O6: 0 | P6: 0
A7: CO23CS201.2 | B7: 2 | C7: 2 | D7: 0 | E7: 1 | F7: 1 | G7: 0 | H7: 0 | I7: 0 | J7: 0 | K7: 0 | L7: 0 | M7: 1 | N7: 0 | O7: 0 | P7: 0
A8: CO23CS201.3 | B8: 2 | C8: 2 | D8: 0 | E8: 1 | F8: 1 | G8: 0 | H8: 0 | I8: 0 | J8: 0 | K8: 0 | L8: 0 | M8: 1 | N8: 0 | O8: 0 | P8: 0
A9: CO23CS201.4 | B9: 2 | C9: 2 | D9: 0 | E9: 1 | F9: 1 | G9: 0 | H9: 0 | I9: 0 | J9: 0 | K9: 0 | L9: 0 | M9: 1 | N9: 0 | O9: 0 | P9: 0
A10: CO23CS201.5 | B10: 2 | C10: 2 | D10: 0 | E10: 1 | F10: 1 | G10: 1 | H10: 0 | I10: 1 | J10: 0 | K10: 0 | L10: 0 | M10: 1 | N10: 0 | O10: 0 | P10: 0
A11: CO35CS203 Avg | B11: =AVERAGE(B6:B10) | C11: =AVERAGE(C6:C10) | D11: =AVERAGE(D6:D10) | E11: =AVERAGE(E6:E10) | F11: =AVERAGE(F6:F10) | G11: =AVERAGE(G6:G10) | H11: =AVERAGE(H6:H10) | I11: =AVERAGE(I6:I10) | ... P11: =AVERAGE(P6:P10)
A12: 3CS2-01 (AVG) | B12: =ROUND(B11,0) | C12: =ROUND(C11,0) | D12: =ROUND(D11,0) | E12: =ROUND(E11,0) | F12: =ROUND(F11,0) | G12: =ROUND(G11,0) | H12: =ROUND(H11,0) | I12: =ROUND(I11,0) | ... P12: =ROUND(P11,0)
A13: Signature Subject Teacher

Sheet Sessional + End Term Assessment
A1: ='CO-PO Mapping'!A1:P1
A2: End Term and Sessional Assessment Sheet
A3: ='CO-PO Mapping'!A3:P3
A4: ='CO-PO Mapping'!A4:P4
A5: S.NO. | B5: RollNo | C5: Name | D5: END TERM MARKS | E5: SESSIONAL MARKS | F5: TOTAL | G5: Course Attainment with Target in %
C6: MAX MARKS | D6: 70 | E6: 30 | F6: =D6+E6 | G6: t_End Term Exam | H6: t_Sessional Exam
A7: Set Target Level | D7: 0.6 | E7: 0.7 | G7: 0.6 | H7: 0.7
A8: 1 | B8: 25ETCAD001 | C8: ABHAY CHOUDHARY | D8: 32 | E8: 29 | F8: =D8+E8 | G8: =IF((D8/$D$6)>=$D$7,1,0) | H8: =IF((E8/$E$6)>=$E$7,1,0)
A9: 2 | B9: 25ETCAD002 | C9: ADITYA PRAMOD | D9: 28 | E9: 27 | F9: =D9+E9 | G9: =IF((D9/$D$6)>=$D$7,1,0) | H9: =IF((E9/$E$6)>=$E$7,1,0)
A10: 3 | B10: 25ETCAD003 | C10: AKSHITA JAIN | D10: 54 | E10: 30 | F10: =D10+E10 | G10: =IF((D10/$D$6)>=$D$7,1,0) | H10: =IF((E10/$E$6)>=$E$7,1,0)
A11: 4 | B11: 25ETCAD004 | C11: ARCHITA GUPTA | D11: 46 | E11: 27 | F11: =D11+E11 | G11: =IF((D11/$D$6)>=$D$7,1,0) | H11: =IF((E11/$E$6)>=$E$7,1,0)
A12: 5 | B12: 25ETCAD005 | C12: BHAVESH JOSHI | D12: 6 | E12: 24 | F12: =D12+E12 | G12: =IF((D12/$D$6)>=$D$7,1,0) | H12: =IF((E12/$E$6)>=$E$7,1,0)
A13: 6 | B13: 25ETCAD006 | C13: DHAIRYA MENARIYA | D13: 17 | E13: 28 | F13: =D13+E13 | G13: =IF((D13/$D$6)>=$D$7,1,0) | H13: =IF((E13/$E$6)>=$E$7,1,0)
A14: 7 | B14: 25ETCAD007 | C14: DIVYANSH SETH | D14: 37 | E14: 28 | F14: =D14+E14 | G14: =IF((D14/$D$6)>=$D$7,1,0) | H14: =IF((E14/$E$6)>=$E$7,1,0)
A15: 8 | B15: 25ETCAD008 | C15: HEMANSHU MEHTA | D15: 26 | E15: 27 | F15: =D15+E15 | G15: =IF((D15/$D$6)>=$D$7,1,0) | H15: =IF((E15/$E$6)>=$E$7,1,0)
A16: 9 | B16: 25ETCAD009 | C16: JOGESH RATHI | D16: 11 | E16: 28 | F16: =D16+E16 | G16: =IF((D16/$D$6)>=$D$7,1,0) | H16: =IF((E16/$E$6)>=$E$7,1,0)
A17: 10 | B17: 25ETCAD010 | C17: KARAN SINGH RATHORE | D17: 38 | E17: 29 | F17: =D17+E17 | G17: =IF((D17/$D$6)>=$D$7,1,0) | H17: =IF((E17/$E$6)>=$E$7,1,0)
A18: 11 | B18: 25ETCAD011 | C18: KUSHAGRA BHATT | D18: 11 | E18: 26 | F18: =D18+E18 | G18: =IF((D18/$D$6)>=$D$7,1,0) | H18: =IF((E18/$E$6)>=$E$7,1,0)
A19: 12 | B19: 25ETCAD012 | C19: KUSHAGRA MENARIA | D19: 38 | E19: 28 | F19: =D19+E19 | G19: =IF((D19/$D$6)>=$D$7,1,0) | H19: =IF((E19/$E$6)>=$E$7,1,0)
... A256: 249 | B256: 25ETCEC027 | C256: YASH SONI | D256: 20 | E256: 26 | F256: =D256+E256 | G256: =IF((D256/$D$6)>=$D$7,1,0) | H256: =IF((E256/$E$6)>=$E$7,1,0)
D257: 249 | E257: 249 | G257: =COUNTIF(G8:G256,1) | H257: =COUNTIF(H8:H256,1)
A258: CO Attainment Calculation | D258: % of students get >= Target % | E258: CO Attainment Level | F258: Signature Subject Teacher
A259: Attainment of End Term Exam | D259: =ROUND((G257/D257*100),0) | E259: =IF(D259>100,"ERROR",IF(D259>=61,3,IF(D259>=46,2,IF(D259>=16,1,IF(D259>15,0,0)))))
A260: Attainment of Sessional Exam | D260: =ROUND((H257/E257*100),0) | E260: =IF(D260>100,"ERROR",IF(D260>=61,3,IF(D260>=46,2,IF(D260>=16,1,IF(D260>15,0,0)))))

Sheet Attainment of Subject Code
A1: ='CO-PO Mapping'!A1:P1
A2: Attainment of Subject
A3: ='CO-PO Mapping'!A3:P3
A4: ='CO-PO Mapping'!A4:P4
A5: Course code as per NBA | B5: Subject Code | C5: % of students securing 60% or more Marks in theory | D5: Attainment Level | E5: Attainment Level considering 80% weightage | F5: % of students securing 75% or more Marks in sessional | G5: Attainment Level | H5: Attainment Level considering 20% weightage | I5: Total Attinment
A6: ='CO-PO Mapping'!A11 | B6: 5CS2-03 | C6: ='Sessional + End Term Assessment'!D259 | D6: ='Sessional + End Term Assessment'!E259 | E6: =D6*'Sessional + End Term Assessment'!D6/'Sessional + End Term Assessment'!F6 | F6: ='Sessional + End Term Assessment'!D260 | G6: ='Sessional + End Term Assessment'!E260 | H6: =G6*'Sessional + End Term Assessment'!E6/'Sessional + End Term Assessment'!F6 | I6: =E6+H6
A7: Signature HOD | G7: Signature Subject Teacher

Sheet Attainment Tool 1 C to PO
A1: ='CO-PO Mapping'!A1:P1
A2: CO to PO & PSO Attainment Through End Term Assessment
A3: ='CO-PO Mapping'!A4:P4
A5: Course | B5: PO1 | C5: PO2 | D5: PO3 | E5: PO4 | F5: PO5 | G5: PO6 | H5: PO7 | I5: PO8 | J5: PO9 | K5: PO10 | L5: PO11 | M5: PO12 | N5: PSO1 | O5: PSO2 | P5: PSO3
A6: ='CO-PO Mapping'!A11 | B6: ='Attainment of Subject Code'!$I$6*'CO-PO Mapping'!B12/3 | C6: ='Attainment of Subject Code'!$I$6*'CO-PO Mapping'!C12/3 | D6: ='Attainment of Subject Code'!$I$6*'CO-PO Mapping'!D12/3 | E6: ='Attainment of Subject Code'!$I$6*'CO-PO Mapping'!E12/3 | F6: ='Attainment of Subject Code'!$I$6*'CO-PO Mapping'!F12/3 | G6: ='Attainment of Subject Code'!$I$6*'CO-PO Mapping'!G12/3 | H6: ='Attainment of Subject Code'!$I$6*'CO-PO Mapping'!H12/3 | I6: ='Attainment of Subject Code'!$I$6*'CO-PO Mapping'!I12/3 | ... P6: ='Attainment of Subject Code'!$I$6*'CO-PO Mapping'!P12/3
A7: Signature Subject Teacher

Sheet MID Term 1
A1: ='CO-PO Mapping'!A1:R1
A2: MID TERM I EXAM MARK RECORD
A3: ='CO-PO Mapping'!A3:R3
A4: S.NO. | B4: RollNo | C4: NAME OF STUDENT | R4: MT1
C5: CO MAPPED | D5: CO1 | E5: Target 70% students attain 70% marks (1) | F5: Target 70% students attain 80% marks (2) | G5: Target 70% students attain 90% marks (3) | H5: CO2 | I5: Target 70% students attain 70% marks (1) | J5: Target 70% students attain 80% marks (2) | K5: Target 70% students attain 90% marks (3) | L5: CO3 | M5: Target 50% students attain 70% marks (1) | N5: Target 50% students attain 80% marks (2) | O5: Target 50% students attain 90% marks (3) | P5: CO4 | Q5: CO5
C6: MAX MARKS | D6: 28 | H6: 28 | L6: 14 | R6: 70
A7: ='Sessional + End Term Assessment'!A8 | B7: ='Sessional + End Term Assessment'!B8 | C7: ='Sessional + End Term Assessment'!C8 | D7: 27 | E7: =IF(D7>=($D$6*0.7),1,0) | F7: =IF(D7>=($D$6*0.8),1,0) | G7: =IF(D7>=($D$6*0.9),1,0) | H7: 27 | I7: =IF(H7>=($H$6*0.7),1,0) | J7: =IF(H7>=($H$6*0.7),1,0) | K7: =IF(H7>=($H$6*0.9),1,0) | L7: 14 | M7: =IF(L7>=($L$6*0.7),1,0) | N7: =IF(L7>=($L$6*0.8),1,0) | O7: =IF(L7>=($L$6*0.9),1,0) | R7: 68
A8: ='Sessional + End Term Assessment'!A9 | B8: ='Sessional + End Term Assessment'!B9 | C8: ='Sessional + End Term Assessment'!C9 | D8: 23 | E8: =IF(D8>=($D$6*0.7),1,0) | F8: =IF(D8>=($D$6*0.8),1,0) | G8: =IF(D8>=($D$6*0.9),1,0) | H8: 26 | I8: =IF(H8>=($H$6*0.7),1,0) | J8: =IF(H8>=($H$6*0.7),1,0) | K8: =IF(H8>=($H$6*0.9),1,0) | L8: 13 | M8: =IF(L8>=($L$6*0.7),1,0) | N8: =IF(L8>=($L$6*0.8),1,0) | O8: =IF(L8>=($L$6*0.9),1,0) | R8: 62
A9: ='Sessional + End Term Assessment'!A10 | B9: ='Sessional + End Term Assessment'!B10 | C9: ='Sessional + End Term Assessment'!C10 | D9: 28 | E9: =IF(D9>=($D$6*0.7),1,0) | F9: =IF(D9>=($D$6*0.8),1,0) | G9: =IF(D9>=($D$6*0.9),1,0) | H9: 28 | I9: =IF(H9>=($H$6*0.7),1,0) | J9: =IF(H9>=($H$6*0.7),1,0) | K9: =IF(H9>=($H$6*0.9),1,0) | L9: 14 | M9: =IF(L9>=($L$6*0.7),1,0) | N9: =IF(L9>=($L$6*0.8),1,0) | O9: =IF(L9>=($L$6*0.9),1,0) | R9: 70
A10: ='Sessional + End Term Assessment'!A11 | B10: ='Sessional + End Term Assessment'!B11 | C10: ='Sessional + End Term Assessment'!C11 | D10: 24 | E10: =IF(D10>=($D$6*0.7),1,0) | F10: =IF(D10>=($D$6*0.8),1,0) | G10: =IF(D10>=($D$6*0.9),1,0) | H10: 24 | I10: =IF(H10>=($H$6*0.7),1,0) | J10: =IF(H10>=($H$6*0.7),1,0) | K10: =IF(H10>=($H$6*0.9),1,0) | L10: 13 | M10: =IF(L10>=($L$6*0.7),1,0) | N10: =IF(L10>=($L$6*0.8),1,0) | O10: =IF(L10>=($L$6*0.9),1,0) | R10: 61
A11: ='Sessional + End Term Assessment'!A12 | B11: ='Sessional + End Term Assessment'!B12 | C11: ='Sessional + End Term Assessment'!C12 | D11: 24 | E11: =IF(D11>=($D$6*0.7),1,0) | F11: =IF(D11>=($D$6*0.8),1,0) | G11: =IF(D11>=($D$6*0.9),1,0) | H11: 21 | I11: =IF(H11>=($H$6*0.7),1,0) | J11: =IF(H11>=($H$6*0.7),1,0) | K11: =IF(H11>=($H$6*0.9),1,0) | L11: 13 | M11: =IF(L11>=($L$6*0.7),1,0) | N11: =IF(L11>=($L$6*0.8),1,0) | O11: =IF(L11>=($L$6*0.9),1,0) | R11: 58
A12: ='Sessional + End Term Assessment'!A13 | B12: ='Sessional + End Term Assessment'!B13 | C12: ='Sessional + End Term Assessment'!C13 | D12: 25 | E12: =IF(D12>=($D$6*0.7),1,0) | F12: =IF(D12>=($D$6*0.8),1,0) | G12: =IF(D12>=($D$6*0.9),1,0) | H12: 26 | I12: =IF(H12>=($H$6*0.7),1,0) | J12: =IF(H12>=($H$6*0.7),1,0) | K12: =IF(H12>=($H$6*0.9),1,0) | L12: 14 | M12: =IF(L12>=($L$6*0.7),1,0) | N12: =IF(L12>=($L$6*0.8),1,0) | O12: =IF(L12>=($L$6*0.9),1,0) | R12: 65
A13: ='Sessional + End Term Assessment'!A14 | B13: ='Sessional + End Term Assessment'!B14 | C13: ='Sessional + End Term Assessment'!C14 | D13: 24 | E13: =IF(D13>=($D$6*0.7),1,0) | F13: =IF(D13>=($D$6*0.8),1,0) | G13: =IF(D13>=($D$6*0.9),1,0) | H13: 27 | I13: =IF(H13>=($H$6*0.7),1,0) | J13: =IF(H13>=($H$6*0.7),1,0) | K13: =IF(H13>=($H$6*0.9),1,0) | L13: 14 | M13: =IF(L13>=($L$6*0.7),1,0) | N13: =IF(L13>=($L$6*0.8),1,0) | O13: =IF(L13>=($L$6*0.9),1,0) | R13: 65
A14: ='Sessional + End Term Assessment'!A15 | B14: ='Sessional + End Term Assessment'!B15 | C14: ='Sessional + End Term Assessment'!C15 | D14: 25 | E14: =IF(D14>=($D$6*0.7),1,0) | F14: =IF(D14>=($D$6*0.8),1,0) | G14: =IF(D14>=($D$6*0.9),1,0) | H14: 24 | I14: =IF(H14>=($H$6*0.7),1,0) | J14: =IF(H14>=($H$6*0.7),1,0) | K14: =IF(H14>=($H$6*0.9),1,0) | L14: 13 | M14: =IF(L14>=($L$6*0.7),1,0) | N14: =IF(L14>=($L$6*0.8),1,0) | O14: =IF(L14>=($L$6*0.9),1,0) | R14: 62
A15: ='Sessional + End Term Assessment'!A16 | B15: ='Sessional + End Term Assessment'!B16 | C15: ='Sessional + End Term Assessment'!C16 | D15: 26 | E15: =IF(D15>=($D$6*0.7),1,0) | F15: =IF(D15>=($D$6*0.8),1,0) | G15: =IF(D15>=($D$6*0.9),1,0) | H15: 26 | I15: =IF(H15>=($H$6*0.7),1,0) | J15: =IF(H15>=($H$6*0.7),1,0) | K15: =IF(H15>=($H$6*0.9),1,0) | L15: 14 | M15: =IF(L15>=($L$6*0.7),1,0) | N15: =IF(L15>=($L$6*0.8),1,0) | O15: =IF(L15>=($L$6*0.9),1,0) | R15: 66
A16: ='Sessional + End Term Assessment'!A17 | B16: ='Sessional + End Term Assessment'!B17 | C16: ='Sessional + End Term Assessment'!C17 | D16: 26 | E16: =IF(D16>=($D$6*0.7),1,0) | F16: =IF(D16>=($D$6*0.8),1,0) | G16: =IF(D16>=($D$6*0.9),1,0) | H16: 26 | I16: =IF(H16>=($H$6*0.7),1,0) | J16: =IF(H16>=($H$6*0.7),1,0) | K16: =IF(H16>=($H$6*0.9),1,0) | L16: 14 | M16: =IF(L16>=($L$6*0.7),1,0) | N16: =IF(L16>=($L$6*0.8),1,0) | O16: =IF(L16>=($L$6*0.9),1,0) | R16: 66
A17: ='Sessional + End Term Assessment'!A18 | B17: ='Sessional + End Term Assessment'!B18 | C17: ='Sessional + End Term Assessment'!C18 | D17: 25 | E17: =IF(D17>=($D$6*0.7),1,0) | F17: =IF(D17>=($D$6*0.8),1,0) | G17: =IF(D17>=($D$6*0.9),1,0) | H17: 25 | I17: =IF(H17>=($H$6*0.7),1,0) | J17: =IF(H17>=($H$6*0.7),1,0) | K17: =IF(H17>=($H$6*0.9),1,0) | L17: 13 | M17: =IF(L17>=($L$6*0.7),1,0) | N17: =IF(L17>=($L$6*0.8),1,0) | O17: =IF(L17>=($L$6*0.9),1,0) | R17: 63
A18: ='Sessional + End Term Assessment'!A19 | B18: ='Sessional + End Term Assessment'!B19 | C18: ='Sessional + End Term Assessment'!C19 | D18: 24 | E18: =IF(D18>=($D$6*0.7),1,0) | F18: =IF(D18>=($D$6*0.8),1,0) | G18: =IF(D18>=($D$6*0.9),1,0) | H18: 27 | I18: =IF(H18>=($H$6*0.7),1,0) | J18: =IF(H18>=($H$6*0.7),1,0) | K18: =IF(H18>=($H$6*0.9),1,0) | L18: 14 | M18: =IF(L18>=($L$6*0.7),1,0) | N18: =IF(L18>=($L$6*0.8),1,0) | O18: =IF(L18>=($L$6*0.9),1,0) | R18: 65
... A255: ='Sessional + End Term Assessment'!A256 | B255: ='Sessional + End Term Assessment'!B256 | C255: ='Sessional + End Term Assessment'!C256 | D255: 26 | E255: =IF(D255>=($D$6*0.7),1,0) | F255: =IF(D255>=($D$6*0.8),1,0) | G255: =IF(D255>=($D$6*0.9),1,0) | H255: 23 | I255: =IF(H255>=($H$6*0.7),1,0) | J255: =IF(H255>=($H$6*0.7),1,0) | K255: =IF(H255>=($H$6*0.9),1,0) | L255: 13 | M255: =IF(L255>=($L$6*0.7),1,0) | N255: =IF(L255>=($L$6*0.8),1,0) | O255: =IF(L255>=($L$6*0.9),1,0) | R255: 62

Sheet REMIDAL 1
A1: Marks and Gap Analysis of Mid-Term 1
A2: Sr. No | B2: RTU Roll Number | C2: Name of the Student | D2: M-1 Marks (70) | E2: Remark ( Remedial Class need or not – Y/N )
A3: ='Sessional + End Term Assessment'!A8 | B3: ='Sessional + End Term Assessment'!B8 | C3: ='Sessional + End Term Assessment'!C8 | D3: ='MID Term 1'!R7 | E3: =IF(D3<=30,"Y","N")
A4: ='Sessional + End Term Assessment'!A9 | B4: ='Sessional + End Term Assessment'!B9 | C4: ='Sessional + End Term Assessment'!C9 | D4: ='MID Term 1'!R8 | E4: =IF(D4<=30,"Y","N")
A5: ='Sessional + End Term Assessment'!A10 | B5: ='Sessional + End Term Assessment'!B10 | C5: ='Sessional + End Term Assessment'!C10 | D5: ='MID Term 1'!R9 | E5: =IF(D5<=30,"Y","N")
A6: ='Sessional + End Term Assessment'!A11 | B6: ='Sessional + End Term Assessment'!B11 | C6: ='Sessional + End Term Assessment'!C11 | D6: ='MID Term 1'!R10 | E6: =IF(D6<=30,"Y","N")
A7: ='Sessional + End Term Assessment'!A12 | B7: ='Sessional + End Term Assessment'!B12 | C7: ='Sessional + End Term Assessment'!C12 | D7: ='MID Term 1'!R11 | E7: =IF(D7<=30,"Y","N")
A8: ='Sessional + End Term Assessment'!A13 | B8: ='Sessional + End Term Assessment'!B13 | C8: ='Sessional + End Term Assessment'!C13 | D8: ='MID Term 1'!R12 | E8: =IF(D8<=30,"Y","N")
A9: ='Sessional + End Term Assessment'!A14 | B9: ='Sessional + End Term Assessment'!B14 | C9: ='Sessional + End Term Assessment'!C14 | D9: ='MID Term 1'!R13 | E9: =IF(D9<=30,"Y","N")
A10: ='Sessional + End Term Assessment'!A15 | B10: ='Sessional + End Term Assessment'!B15 | C10: ='Sessional + End Term Assessment'!C15 | D10: ='MID Term 1'!R14 | E10: =IF(D10<=30,"Y","N")
A11: ='Sessional + End Term Assessment'!A16 | B11: ='Sessional + End Term Assessment'!B16 | C11: ='Sessional + End Term Assessment'!C16 | D11: ='MID Term 1'!R15 | E11: =IF(D11<=30,"Y","N")
A12: ='Sessional + End Term Assessment'!A17 | B12: ='Sessional + End Term Assessment'!B17 | C12: ='Sessional + End Term Assessment'!C17 | D12: ='MID Term 1'!R16 | E12: =IF(D12<=30,"Y","N")
A13: ='Sessional + End Term Assessment'!A18 | B13: ='Sessional + End Term Assessment'!B18 | C13: ='Sessional + End Term Assessment'!C18 | D13: ='MID Term 1'!R17 | E13: =IF(D13<=30,"Y","N")
A14: ='Sessional + End Term Assessment'!A19 | B14: ='Sessional + End Term Assessment'!B19 | C14: ='Sessional + End Term Assessment'!C19 | D14: ='MID Term 1'!R18 | E14: =IF(D14<=30,"Y","N")
... A251: ='Sessional + End Term Assessment'!A256 | B251: ='Sessional + End Term Assessment'!B256 | C251: ='Sessional + End Term Assessment'!C256 | D251: ='MID Term 1'!R255 | E251: =IF(D251<=30,"Y","N")

Sheet MID Term 2
A1: ='CO-PO Mapping'!A1:P1
A2: MID TERM II EXAM MARK RECORD
A3: ='CO-PO Mapping'!A3:P3
A4: S.NO. | B4: RTU ROLL NUMBER | C4: NAME OF STUDENT | R4: MT2
C5: CO MAPPED | D5: CO1 | E5: CO2 | F5: CO3 | G5: Target 50% students attain 70% marks (1) | H5: Target 50% students attain 80% marks (2) | I5: Target 50% students attain 90% marks (3) | J5: CO4 | K5: Target 50% students attain 70% marks (1) | L5: Target 50% students attain 80% marks (2) | M5: Target 50% students attain 90% marks (3) | N5: CO5 | O5: Target 50% students attain 70% marks (1) | P5: Target 50% students attain 80% marks (2) | Q5: Target 50% students attain 90% marks (3)
C6: MAX MARKS | F6: 14 | J6: 28 | N6: 28 | R6: =SUM(F6:N6)
A7: ='Sessional + End Term Assessment'!A8 | B7: ='Sessional + End Term Assessment'!B8 | C7: ='Sessional + End Term Assessment'!C8 | F7: 14 | G7: =IF(F7>=($F$6*0.5),1,0) | H7: =IF(F7>=($F$6*0.6),1,0) | I7: =IF(F7>=($F$6*0.7),1,0) | J7: 27 | K7: =IF(J7>=($J$6*0.7),1,0) | L7: =IF(J7>=($J$6*0.8),1,0) | M7: =IF(J7>=($J$6*0.9),1,0) | N7: 27 | O7: =IF(N7>=($N$6*0.7),1,0) | P7: =IF(N7>=($N$6*0.8),1,0) | Q7: =IF(N7>=($N$6*0.9),1,0) | R7: 68
A8: ='Sessional + End Term Assessment'!A9 | B8: ='Sessional + End Term Assessment'!B9 | C8: ='Sessional + End Term Assessment'!C9 | F8: 13 | G8: =IF(F8>=($F$6*0.5),1,0) | H8: =IF(F8>=($F$6*0.6),1,0) | I8: =IF(F8>=($F$6*0.7),1,0) | J8: 24 | K8: =IF(J8>=($J$6*0.7),1,0) | L8: =IF(J8>=($J$6*0.8),1,0) | M8: =IF(J8>=($J$6*0.9),1,0) | N8: 27 | O8: =IF(N8>=($N$6*0.7),1,0) | P8: =IF(N8>=($N$6*0.8),1,0) | Q8: =IF(N8>=($N$6*0.9),1,0) | R8: 64
A9: ='Sessional + End Term Assessment'!A10 | B9: ='Sessional + End Term Assessment'!B10 | C9: ='Sessional + End Term Assessment'!C10 | F9: 14 | G9: =IF(F9>=($F$6*0.5),1,0) | H9: =IF(F9>=($F$6*0.6),1,0) | I9: =IF(F9>=($F$6*0.7),1,0) | J9: 28 | K9: =IF(J9>=($J$6*0.7),1,0) | L9: =IF(J9>=($J$6*0.8),1,0) | M9: =IF(J9>=($J$6*0.9),1,0) | N9: 28 | O9: =IF(N9>=($N$6*0.7),1,0) | P9: =IF(N9>=($N$6*0.8),1,0) | Q9: =IF(N9>=($N$6*0.9),1,0) | R9: 70
A10: ='Sessional + End Term Assessment'!A11 | B10: ='Sessional + End Term Assessment'!B11 | C10: ='Sessional + End Term Assessment'!C11 | F10: 14 | G10: =IF(F10>=($F$6*0.5),1,0) | H10: =IF(F10>=($F$6*0.6),1,0) | I10: =IF(F10>=($F$6*0.7),1,0) | J10: 27 | K10: =IF(J10>=($J$6*0.7),1,0) | L10: =IF(J10>=($J$6*0.8),1,0) | M10: =IF(J10>=($J$6*0.9),1,0) | N10: 24 | O10: =IF(N10>=($N$6*0.7),1,0) | P10: =IF(N10>=($N$6*0.8),1,0) | Q10: =IF(N10>=($N$6*0.9),1,0) | R10: 65
A11: ='Sessional + End Term Assessment'!A12 | B11: ='Sessional + End Term Assessment'!B12 | C11: ='Sessional + End Term Assessment'!C12 | F11: 11 | G11: =IF(F11>=($F$6*0.5),1,0) | H11: =IF(F11>=($F$6*0.6),1,0) | I11: =IF(F11>=($F$6*0.7),1,0) | J11: 23 | K11: =IF(J11>=($J$6*0.7),1,0) | L11: =IF(J11>=($J$6*0.8),1,0) | M11: =IF(J11>=($J$6*0.9),1,0) | N11: 20 | O11: =IF(N11>=($N$6*0.7),1,0) | P11: =IF(N11>=($N$6*0.8),1,0) | Q11: =IF(N11>=($N$6*0.9),1,0) | R11: 54
A12: ='Sessional + End Term Assessment'!A13 | B12: ='Sessional + End Term Assessment'!B13 | C12: ='Sessional + End Term Assessment'!C13 | F12: 14 | G12: =IF(F12>=($F$6*0.5),1,0) | H12: =IF(F12>=($F$6*0.6),1,0) | I12: =IF(F12>=($F$6*0.7),1,0) | J12: 25 | K12: =IF(J12>=($J$6*0.7),1,0) | L12: =IF(J12>=($J$6*0.8),1,0) | M12: =IF(J12>=($J$6*0.9),1,0) | N12: 26 | O12: =IF(N12>=($N$6*0.7),1,0) | P12: =IF(N12>=($N$6*0.8),1,0) | Q12: =IF(N12>=($N$6*0.9),1,0) | R12: 65
A13: ='Sessional + End Term Assessment'!A14 | B13: ='Sessional + End Term Assessment'!B14 | C13: ='Sessional + End Term Assessment'!C14 | F13: 14 | G13: =IF(F13>=($F$6*0.5),1,0) | H13: =IF(F13>=($F$6*0.6),1,0) | I13: =IF(F13>=($F$6*0.7),1,0) | J13: 24 | K13: =IF(J13>=($J$6*0.7),1,0) | L13: =IF(J13>=($J$6*0.8),1,0) | M13: =IF(J13>=($J$6*0.9),1,0) | N13: 27 | O13: =IF(N13>=($N$6*0.7),1,0) | P13: =IF(N13>=($N$6*0.8),1,0) | Q13: =IF(N13>=($N$6*0.9),1,0) | R13: 65
A14: ='Sessional + End Term Assessment'!A15 | B14: ='Sessional + End Term Assessment'!B15 | C14: ='Sessional + End Term Assessment'!C15 | F14: 13 | G14: =IF(F14>=($F$6*0.5),1,0) | H14: =IF(F14>=($F$6*0.6),1,0) | I14: =IF(F14>=($F$6*0.7),1,0) | J14: 26 | K14: =IF(J14>=($J$6*0.7),1,0) | L14: =IF(J14>=($J$6*0.8),1,0) | M14: =IF(J14>=($J$6*0.9),1,0) | N14: 25 | O14: =IF(N14>=($N$6*0.7),1,0) | P14: =IF(N14>=($N$6*0.8),1,0) | Q14: =IF(N14>=($N$6*0.9),1,0) | R14: 64
A15: ='Sessional + End Term Assessment'!A16 | B15: ='Sessional + End Term Assessment'!B16 | C15: ='Sessional + End Term Assessment'!C16 | F15: 13 | G15: =IF(F15>=($F$6*0.5),1,0) | H15: =IF(F15>=($F$6*0.6),1,0) | I15: =IF(F15>=($F$6*0.7),1,0) | J15: 27 | K15: =IF(J15>=($J$6*0.7),1,0) | L15: =IF(J15>=($J$6*0.8),1,0) | M15: =IF(J15>=($J$6*0.9),1,0) | N15: 24 | O15: =IF(N15>=($N$6*0.7),1,0) | P15: =IF(N15>=($N$6*0.8),1,0) | Q15: =IF(N15>=($N$6*0.9),1,0) | R15: 64
A16: ='Sessional + End Term Assessment'!A17 | B16: ='Sessional + End Term Assessment'!B17 | C16: ='Sessional + End Term Assessment'!C17 | F16: 14 | G16: =IF(F16>=($F$6*0.5),1,0) | H16: =IF(F16>=($F$6*0.6),1,0) | I16: =IF(F16>=($F$6*0.7),1,0) | J16: 28 | K16: =IF(J16>=($J$6*0.7),1,0) | L16: =IF(J16>=($J$6*0.8),1,0) | M16: =IF(J16>=($J$6*0.9),1,0) | N16: 28 | O16: =IF(N16>=($N$6*0.7),1,0) | P16: =IF(N16>=($N$6*0.8),1,0) | Q16: =IF(N16>=($N$6*0.9),1,0) | R16: 70
A17: ='Sessional + End Term Assessment'!A18 | B17: ='Sessional + End Term Assessment'!B18 | C17: ='Sessional + End Term Assessment'!C18 | F17: 13 | G17: =IF(F17>=($F$6*0.5),1,0) | H17: =IF(F17>=($F$6*0.6),1,0) | I17: =IF(F17>=($F$6*0.7),1,0) | J17: 23 | K17: =IF(J17>=($J$6*0.7),1,0) | L17: =IF(J17>=($J$6*0.8),1,0) | M17: =IF(J17>=($J$6*0.9),1,0) | N17: 23 | O17: =IF(N17>=($N$6*0.7),1,0) | P17: =IF(N17>=($N$6*0.8),1,0) | Q17: =IF(N17>=($N$6*0.9),1,0) | R17: 59
A18: ='Sessional + End Term Assessment'!A19 | B18: ='Sessional + End Term Assessment'!B19 | C18: ='Sessional + End Term Assessment'!C19 | F18: 14 | G18: =IF(F18>=($F$6*0.5),1,0) | H18: =IF(F18>=($F$6*0.6),1,0) | I18: =IF(F18>=($F$6*0.7),1,0) | J18: 24 | K18: =IF(J18>=($J$6*0.7),1,0) | L18: =IF(J18>=($J$6*0.8),1,0) | M18: =IF(J18>=($J$6*0.9),1,0) | N18: 27 | O18: =IF(N18>=($N$6*0.7),1,0) | P18: =IF(N18>=($N$6*0.8),1,0) | Q18: =IF(N18>=($N$6*0.9),1,0) | R18: 65
... A255: ='Sessional + End Term Assessment'!A256 | B255: ='Sessional + End Term Assessment'!B256 | C255: ='Sessional + End Term Assessment'!C256 | F255: 13 | G255: =IF(F255>=($F$6*0.5),1,0) | H255: =IF(F255>=($F$6*0.6),1,0) | I255: =IF(F255>=($F$6*0.7),1,0) | J255: 25 | K255: =IF(J255>=($J$6*0.7),1,0) | L255: =IF(J255>=($J$6*0.8),1,0) | M255: =IF(J255>=($J$6*0.9),1,0) | N255: 22 | O255: =IF(N255>=($N$6*0.7),1,0) | P255: =IF(N255>=($N$6*0.8),1,0) | Q255: =IF(N255>=($N$6*0.9),1,0) | R255: 60

Sheet REMIDAL 2
A1: Marks and Gap Analysis of Mid-Term 2
A2: Sr. No | B2: RTU Roll Number | C2: Name of the Student | D2: M-2 Marks (70) | E2: Remark ( Remedial Class need or not – Y/N )
A3: ='Sessional + End Term Assessment'!A8 | B3: ='Sessional + End Term Assessment'!B8 | C3: ='Sessional + End Term Assessment'!C8 | D3: ='MID Term 2'!R7 | E3: =IF(D3<=35,"Y","N")
A4: ='Sessional + End Term Assessment'!A9 | B4: ='Sessional + End Term Assessment'!B9 | C4: ='Sessional + End Term Assessment'!C9 | D4: ='MID Term 2'!R8 | E4: =IF(D4<=35,"Y","N")
A5: ='Sessional + End Term Assessment'!A10 | B5: ='Sessional + End Term Assessment'!B10 | C5: ='Sessional + End Term Assessment'!C10 | D5: ='MID Term 2'!R9 | E5: =IF(D5<=35,"Y","N")
A6: ='Sessional + End Term Assessment'!A11 | B6: ='Sessional + End Term Assessment'!B11 | C6: ='Sessional + End Term Assessment'!C11 | D6: ='MID Term 2'!R10 | E6: =IF(D6<=35,"Y","N")
A7: ='Sessional + End Term Assessment'!A12 | B7: ='Sessional + End Term Assessment'!B12 | C7: ='Sessional + End Term Assessment'!C12 | D7: ='MID Term 2'!R11 | E7: =IF(D7<=35,"Y","N")
A8: ='Sessional + End Term Assessment'!A13 | B8: ='Sessional + End Term Assessment'!B13 | C8: ='Sessional + End Term Assessment'!C13 | D8: ='MID Term 2'!R12 | E8: =IF(D8<=35,"Y","N")
A9: ='Sessional + End Term Assessment'!A14 | B9: ='Sessional + End Term Assessment'!B14 | C9: ='Sessional + End Term Assessment'!C14 | D9: ='MID Term 2'!R13 | E9: =IF(D9<=35,"Y","N")
A10: ='Sessional + End Term Assessment'!A15 | B10: ='Sessional + End Term Assessment'!B15 | C10: ='Sessional + End Term Assessment'!C15 | D10: ='MID Term 2'!R14 | E10: =IF(D10<=35,"Y","N")
A11: ='Sessional + End Term Assessment'!A16 | B11: ='Sessional + End Term Assessment'!B16 | C11: ='Sessional + End Term Assessment'!C16 | D11: ='MID Term 2'!R15 | E11: =IF(D11<=35,"Y","N")
A12: ='Sessional + End Term Assessment'!A17 | B12: ='Sessional + End Term Assessment'!B17 | C12: ='Sessional + End Term Assessment'!C17 | D12: ='MID Term 2'!R16 | E12: =IF(D12<=35,"Y","N")
A13: ='Sessional + End Term Assessment'!A18 | B13: ='Sessional + End Term Assessment'!B18 | C13: ='Sessional + End Term Assessment'!C18 | D13: ='MID Term 2'!R17 | E13: =IF(D13<=35,"Y","N")
A14: ='Sessional + End Term Assessment'!A19 | B14: ='Sessional + End Term Assessment'!B19 | C14: ='Sessional + End Term Assessment'!C19 | D14: ='MID Term 2'!R18 | E14: =IF(D14<=35,"Y","N")
... A251: ='Sessional + End Term Assessment'!A256 | B251: ='Sessional + End Term Assessment'!B256 | C251: ='Sessional + End Term Assessment'!C256 | D251: ='MID Term 2'!R255 | E251: =IF(D251<=35,"Y","N")

Sheet Attainment Sheet Sessional
A1: ='CO-PO Mapping'!A1:P1
A2: Course Outcome Attainment Sheet (Sessional)
A3: ='CO-PO Mapping'!A3:P3
A4: ='CO-PO Mapping'!A4:P4
A5: S.NO. | B5: RTU ROLL NUMBER | C5: NAME OF STUDENT | D5: CO23CS201.1 | E5: CO23CS201.2 | F5: CO23CS201.3 | G5: CO23CS201.4 | H5: CO23CS201.5 | I5: Course Attainment with Target in % | N5: TOTAL | O5: TOTAL
C6: CO MAPPED | I6: CO23CS201.1 | J6: CO23CS201.2 | K6: CO23CS201.3 | L6: CO23CS201.4 | M6: CO23CS201.5
D7: TOTAL | E7: TOTAL | F7: TOTAL | G7: TOTAL | H7: TOTAL
C8: MAX MARKS | D8: ='MID Term 1'!D6+'MID Term 2'!D6 | E8: ='MID Term 1'!H6+'MID Term 2'!E6 | F8: ='MID Term 1'!L6+'MID Term 2'!F6 | G8: ='MID Term 1'!P6+'MID Term 2'!J6 | H8: ='MID Term 1'!Q6+'MID Term 2'!N6 | I8: 0.75 | J8: 0.75 | K8: 0.75 | L8: 0.75 | M8: 0.75 | N8: =SUM(D8:H8) | O8: =ROUND(N8/2,0)
A9: Set Target Level | D9: 0.75 | E9: 0.75 | F9: 0.75 | G9: 0.75 | H9: 0.75
A10: 1 | B10: ='Sessional + End Term Assessment'!B8 | C10: ='Sessional + End Term Assessment'!C8 | D10: ='MID Term 1'!D7+'MID Term 2'!D7 | E10: ='MID Term 1'!H7+'MID Term 2'!E7 | F10: ='MID Term 1'!L7+'MID Term 2'!F7 | G10: ='MID Term 1'!P7+'MID Term 2'!J7 | H10: ='MID Term 1'!Q7+'MID Term 2'!N7 | I10: =IF((D10/$D$8)>=$I$8,1,0) | J10: =IF((E10/$E$8)>=$J$8,1,0) | K10: =IF((F10/$F$8)>=$K$8,1,0) | L10: =IF((G10/$G$8)>=$L$8,1,0) | M10: =IF((H10/$H$8)>=$M$8,1,0) | N10: =SUM(D10:H10) | O10: =ROUND(N10/2,0)
A11: 2 | B11: ='Sessional + End Term Assessment'!B9 | C11: ='Sessional + End Term Assessment'!C9 | D11: ='MID Term 1'!D8+'MID Term 2'!D8 | E11: ='MID Term 1'!H8+'MID Term 2'!E8 | F11: ='MID Term 1'!L8+'MID Term 2'!F8 | G11: ='MID Term 1'!P8+'MID Term 2'!J8 | H11: ='MID Term 1'!Q8+'MID Term 2'!N8 | I11: =IF((D11/$D$8)>=$I$8,1,0) | J11: =IF((E11/$E$8)>=$J$8,1,0) | K11: =IF((F11/$F$8)>=$K$8,1,0) | L11: =IF((G11/$G$8)>=$L$8,1,0) | M11: =IF((H11/$H$8)>=$M$8,1,0) | N11: =SUM(D11:H11) | O11: =ROUND(N11/2,0)
A12: 3 | B12: ='Sessional + End Term Assessment'!B10 | C12: ='Sessional + End Term Assessment'!C10 | D12: ='MID Term 1'!D9+'MID Term 2'!D9 | E12: ='MID Term 1'!H9+'MID Term 2'!E9 | F12: ='MID Term 1'!L9+'MID Term 2'!F9 | G12: ='MID Term 1'!P9+'MID Term 2'!J9 | H12: ='MID Term 1'!Q9+'MID Term 2'!N9 | I12: =IF((D12/$D$8)>=$I$8,1,0) | J12: =IF((E12/$E$8)>=$J$8,1,0) | K12: =IF((F12/$F$8)>=$K$8,1,0) | L12: =IF((G12/$G$8)>=$L$8,1,0) | M12: =IF((H12/$H$8)>=$M$8,1,0) | N12: =SUM(D12:H12) | O12: =ROUND(N12/2,0)
A13: 4 | B13: ='Sessional + End Term Assessment'!B11 | C13: ='Sessional + End Term Assessment'!C11 | D13: ='MID Term 1'!D10+'MID Term 2'!D10 | E13: ='MID Term 1'!H10+'MID Term 2'!E10 | F13: ='MID Term 1'!L10+'MID Term 2'!F10 | G13: ='MID Term 1'!P10+'MID Term 2'!J10 | H13: ='MID Term 1'!Q10+'MID Term 2'!N10 | I13: =IF((D13/$D$8)>=$I$8,1,0) | J13: =IF((E13/$E$8)>=$J$8,1,0) | K13: =IF((F13/$F$8)>=$K$8,1,0) | L13: =IF((G13/$G$8)>=$L$8,1,0) | M13: =IF((H13/$H$8)>=$M$8,1,0) | N13: =SUM(D13:H13) | O13: =ROUND(N13/2,0)
A14: 5 | B14: ='Sessional + End Term Assessment'!B12 | C14: ='Sessional + End Term Assessment'!C12 | D14: ='MID Term 1'!D11+'MID Term 2'!D11 | E14: ='MID Term 1'!H11+'MID Term 2'!E11 | F14: ='MID Term 1'!L11+'MID Term 2'!F11 | G14: ='MID Term 1'!P11+'MID Term 2'!J11 | H14: ='MID Term 1'!Q11+'MID Term 2'!N11 | I14: =IF((D14/$D$8)>=$I$8,1,0) | J14: =IF((E14/$E$8)>=$J$8,1,0) | K14: =IF((F14/$F$8)>=$K$8,1,0) | L14: =IF((G14/$G$8)>=$L$8,1,0) | M14: =IF((H14/$H$8)>=$M$8,1,0) | N14: =SUM(D14:H14) | O14: =ROUND(N14/2,0)
A15: 6 | B15: ='Sessional + End Term Assessment'!B13 | C15: ='Sessional + End Term Assessment'!C13 | D15: ='MID Term 1'!D12+'MID Term 2'!D12 | E15: ='MID Term 1'!H12+'MID Term 2'!E12 | F15: ='MID Term 1'!L12+'MID Term 2'!F12 | G15: ='MID Term 1'!P12+'MID Term 2'!J12 | H15: ='MID Term 1'!Q12+'MID Term 2'!N12 | I15: =IF((D15/$D$8)>=$I$8,1,0) | J15: =IF((E15/$E$8)>=$J$8,1,0) | K15: =IF((F15/$F$8)>=$K$8,1,0) | L15: =IF((G15/$G$8)>=$L$8,1,0) | M15: =IF((H15/$H$8)>=$M$8,1,0) | N15: =SUM(D15:H15) | O15: =ROUND(N15/2,0)
A16: 7 | B16: ='Sessional + End Term Assessment'!B14 | C16: ='Sessional + End Term Assessment'!C14 | D16: ='MID Term 1'!D13+'MID Term 2'!D13 | E16: ='MID Term 1'!H13+'MID Term 2'!E13 | F16: ='MID Term 1'!L13+'MID Term 2'!F13 | G16: ='MID Term 1'!P13+'MID Term 2'!J13 | H16: ='MID Term 1'!Q13+'MID Term 2'!N13 | I16: =IF((D16/$D$8)>=$I$8,1,0) | J16: =IF((E16/$E$8)>=$J$8,1,0) | K16: =IF((F16/$F$8)>=$K$8,1,0) | L16: =IF((G16/$G$8)>=$L$8,1,0) | M16: =IF((H16/$H$8)>=$M$8,1,0) | N16: =SUM(D16:H16) | O16: =ROUND(N16/2,0)
A17: 8 | B17: ='Sessional + End Term Assessment'!B15 | C17: ='Sessional + End Term Assessment'!C15 | D17: ='MID Term 1'!D14+'MID Term 2'!D14 | E17: ='MID Term 1'!H14+'MID Term 2'!E14 | F17: ='MID Term 1'!L14+'MID Term 2'!F14 | G17: ='MID Term 1'!P14+'MID Term 2'!J14 | H17: ='MID Term 1'!Q14+'MID Term 2'!N14 | I17: =IF((D17/$D$8)>=$I$8,1,0) | J17: =IF((E17/$E$8)>=$J$8,1,0) | K17: =IF((F17/$F$8)>=$K$8,1,0) | L17: =IF((G17/$G$8)>=$L$8,1,0) | M17: =IF((H17/$H$8)>=$M$8,1,0) | N17: =SUM(D17:H17) | O17: =ROUND(N17/2,0)
A18: 9 | B18: ='Sessional + End Term Assessment'!B16 | C18: ='Sessional + End Term Assessment'!C16 | D18: ='MID Term 1'!D15+'MID Term 2'!D15 | E18: ='MID Term 1'!H15+'MID Term 2'!E15 | F18: ='MID Term 1'!L15+'MID Term 2'!F15 | G18: ='MID Term 1'!P15+'MID Term 2'!J15 | H18: ='MID Term 1'!Q15+'MID Term 2'!N15 | I18: =IF((D18/$D$8)>=$I$8,1,0) | J18: =IF((E18/$E$8)>=$J$8,1,0) | K18: =IF((F18/$F$8)>=$K$8,1,0) | L18: =IF((G18/$G$8)>=$L$8,1,0) | M18: =IF((H18/$H$8)>=$M$8,1,0) | N18: =SUM(D18:H18) | O18: =ROUND(N18/2,0)
A19: 10 | B19: ='Sessional + End Term Assessment'!B17 | C19: ='Sessional + End Term Assessment'!C17 | D19: ='MID Term 1'!D16+'MID Term 2'!D16 | E19: ='MID Term 1'!H16+'MID Term 2'!E16 | F19: ='MID Term 1'!L16+'MID Term 2'!F16 | G19: ='MID Term 1'!P16+'MID Term 2'!J16 | H19: ='MID Term 1'!Q16+'MID Term 2'!N16 | I19: =IF((D19/$D$8)>=$I$8,1,0) | J19: =IF((E19/$E$8)>=$J$8,1,0) | K19: =IF((F19/$F$8)>=$K$8,1,0) | L19: =IF((G19/$G$8)>=$L$8,1,0) | M19: =IF((H19/$H$8)>=$M$8,1,0) | N19: =SUM(D19:H19) | O19: =ROUND(N19/2,0)
A20: 11 | B20: ='Sessional + End Term Assessment'!B18 | C20: ='Sessional + End Term Assessment'!C18 | D20: ='MID Term 1'!D17+'MID Term 2'!D17 | E20: ='MID Term 1'!H17+'MID Term 2'!E17 | F20: ='MID Term 1'!L17+'MID Term 2'!F17 | G20: ='MID Term 1'!P17+'MID Term 2'!J17 | H20: ='MID Term 1'!Q17+'MID Term 2'!N17 | I20: =IF((D20/$D$8)>=$I$8,1,0) | J20: =IF((E20/$E$8)>=$J$8,1,0) | K20: =IF((F20/$F$8)>=$K$8,1,0) | L20: =IF((G20/$G$8)>=$L$8,1,0) | M20: =IF((H20/$H$8)>=$M$8,1,0) | N20: =SUM(D20:H20) | O20: =ROUND(N20/2,0)
A21: 12 | B21: ='Sessional + End Term Assessment'!B19 | C21: ='Sessional + End Term Assessment'!C19 | D21: ='MID Term 1'!D18+'MID Term 2'!D18 | E21: ='MID Term 1'!H18+'MID Term 2'!E18 | F21: ='MID Term 1'!L18+'MID Term 2'!F18 | G21: ='MID Term 1'!P18+'MID Term 2'!J18 | H21: ='MID Term 1'!Q18+'MID Term 2'!N18 | I21: =IF((D21/$D$8)>=$I$8,1,0) | J21: =IF((E21/$E$8)>=$J$8,1,0) | K21: =IF((F21/$F$8)>=$K$8,1,0) | L21: =IF((G21/$G$8)>=$L$8,1,0) | M21: =IF((H21/$H$8)>=$M$8,1,0) | N21: =SUM(D21:H21) | O21: =ROUND(N21/2,0)
... A221: 212 | B221: ='Sessional + End Term Assessment'!B219 | C221: ='Sessional + End Term Assessment'!C219 | D221: ='MID Term 1'!D218+'MID Term 2'!D218 | E221: ='MID Term 1'!H218+'MID Term 2'!E218 | F221: ='MID Term 1'!L218+'MID Term 2'!F218 | G221: ='MID Term 1'!P218+'MID Term 2'!J218 | H221: ='MID Term 1'!Q218+'MID Term 2'!N218 | I221: =IF((D221/$D$8)>=$I$8,1,0) | J221: =IF((E221/$E$8)>=$J$8,1,0) | K221: =IF((F221/$F$8)>=$K$8,1,0) | L221: =IF((G221/$G$8)>=$L$8,1,0) | M221: =IF((H221/$H$8)>=$M$8,1,0) | N221: =SUM(D221:H221) | O221: =ROUND(N221/2,0)
A222: 213 | B222: ='Sessional + End Term Assessment'!B257 | C222: ='Sessional + End Term Assessment'!C257 | D222: ='MID Term 1'!D219+'MID Term 2'!D219 | E222: ='MID Term 1'!H219+'MID Term 2'!E219 | F222: ='MID Term 1'!L219+'MID Term 2'!F219 | G222: ='MID Term 1'!P219+'MID Term 2'!J219 | H222: ='MID Term 1'!Q219+'MID Term 2'!N219 | I222: =IF((D222/$D$8)>=$I$8,1,0) | J222: =IF((E222/$E$8)>=$J$8,1,0) | K222: =IF((F222/$F$8)>=$K$8,1,0) | L222: =IF((G222/$G$8)>=$L$8,1,0) | M222: =IF((H222/$H$8)>=$M$8,1,0) | N222: =SUM(D222:H222) | O222: =ROUND(N222/2,0)
A223: 214 | B223: ='Sessional + End Term Assessment'!B258 | C223: ='Sessional + End Term Assessment'!C258 | D223: ='MID Term 1'!D220+'MID Term 2'!D220 | E223: ='MID Term 1'!H220+'MID Term 2'!E220 | F223: ='MID Term 1'!L220+'MID Term 2'!F220 | G223: ='MID Term 1'!P220+'MID Term 2'!J220 | H223: ='MID Term 1'!Q220+'MID Term 2'!N220 | I223: =IF((D223/$D$8)>=$I$8,1,0) | J223: =IF((E223/$E$8)>=$J$8,1,0) | K223: =IF((F223/$F$8)>=$K$8,1,0) | L223: =IF((G223/$G$8)>=$L$8,1,0) | M223: =IF((H223/$H$8)>=$M$8,1,0) | N223: =SUM(D223:H223) | O223: =ROUND(N223/2,0)
A224: 215 | B224: ='Sessional + End Term Assessment'!B259 | C224: ='Sessional + End Term Assessment'!C259 | D224: ='MID Term 1'!D221+'MID Term 2'!D221 | E224: ='MID Term 1'!H221+'MID Term 2'!E221 | F224: ='MID Term 1'!L221+'MID Term 2'!F221 | G224: ='MID Term 1'!P221+'MID Term 2'!J221 | H224: ='MID Term 1'!Q221+'MID Term 2'!N221 | I224: =IF((D224/$D$8)>=$I$8,1,0) | J224: =IF((E224/$E$8)>=$J$8,1,0) | K224: =IF((F224/$F$8)>=$K$8,1,0) | L224: =IF((G224/$G$8)>=$L$8,1,0) | M224: =IF((H224/$H$8)>=$M$8,1,0) | N224: =SUM(D224:H224) | O224: =ROUND(N224/2,0)
A225: 216 | B225: ='Sessional + End Term Assessment'!B260 | C225: ='Sessional + End Term Assessment'!C260 | D225: ='MID Term 1'!D222+'MID Term 2'!D222 | E225: ='MID Term 1'!H222+'MID Term 2'!E222 | F225: ='MID Term 1'!L222+'MID Term 2'!F222 | G225: ='MID Term 1'!P222+'MID Term 2'!J222 | H225: ='MID Term 1'!Q222+'MID Term 2'!N222 | I225: =IF((D225/$D$8)>=$I$8,1,0) | J225: =IF((E225/$E$8)>=$J$8,1,0) | K225: =IF((F225/$F$8)>=$K$8,1,0) | L225: =IF((G225/$G$8)>=$L$8,1,0) | M225: =IF((H225/$H$8)>=$M$8,1,0) | N225: =SUM(D225:H225) | O225: =ROUND(N225/2,0)
A226: 217 | B226: ='Sessional + End Term Assessment'!B261 | C226: ='Sessional + End Term Assessment'!C261 | D226: ='MID Term 1'!D223+'MID Term 2'!D223 | E226: ='MID Term 1'!H223+'MID Term 2'!E223 | F226: ='MID Term 1'!L223+'MID Term 2'!F223 | G226: ='MID Term 1'!P223+'MID Term 2'!J223 | H226: ='MID Term 1'!Q223+'MID Term 2'!N223 | I226: =IF((D226/$D$8)>=$I$8,1,0) | J226: =IF((E226/$E$8)>=$J$8,1,0) | K226: =IF((F226/$F$8)>=$K$8,1,0) | L226: =IF((G226/$G$8)>=$L$8,1,0) | M226: =IF((H226/$H$8)>=$M$8,1,0) | N226: =SUM(D226:H226) | O226: =ROUND(N226/2,0)
A227: 218 | B227: ='Sessional + End Term Assessment'!B262 | C227: ='Sessional + End Term Assessment'!C262 | D227: ='MID Term 1'!D224+'MID Term 2'!D224 | E227: ='MID Term 1'!H224+'MID Term 2'!E224 | F227: ='MID Term 1'!L224+'MID Term 2'!F224 | G227: ='MID Term 1'!P224+'MID Term 2'!J224 | H227: ='MID Term 1'!Q224+'MID Term 2'!N224 | I227: =IF((D227/$D$8)>=$I$8,1,0) | J227: =IF((E227/$E$8)>=$J$8,1,0) | K227: =IF((F227/$F$8)>=$K$8,1,0) | L227: =IF((G227/$G$8)>=$L$8,1,0) | M227: =IF((H227/$H$8)>=$M$8,1,0) | N227: =SUM(D227:H227) | O227: =ROUND(N227/2,0)
A228: 219 | B228: ='Sessional + End Term Assessment'!B263 | C228: ='Sessional + End Term Assessment'!C263 | D228: ='MID Term 1'!D225+'MID Term 2'!D225 | E228: ='MID Term 1'!H225+'MID Term 2'!E225 | F228: ='MID Term 1'!L225+'MID Term 2'!F225 | G228: ='MID Term 1'!P225+'MID Term 2'!J225 | H228: ='MID Term 1'!Q225+'MID Term 2'!N225 | I228: =IF((D228/$D$8)>=$I$8,1,0) | J228: =IF((E228/$E$8)>=$J$8,1,0) | K228: =IF((F228/$F$8)>=$K$8,1,0) | L228: =IF((G228/$G$8)>=$L$8,1,0) | M228: =IF((H228/$H$8)>=$M$8,1,0) | N228: =SUM(D228:H228) | O228: =ROUND(N228/2,0)
A229: 220 | B229: ='Sessional + End Term Assessment'!B264 | C229: ='Sessional + End Term Assessment'!C264 | D229: ='MID Term 1'!D226+'MID Term 2'!D226 | E229: ='MID Term 1'!H226+'MID Term 2'!E226 | F229: ='MID Term 1'!L226+'MID Term 2'!F226 | G229: ='MID Term 1'!P226+'MID Term 2'!J226 | H229: ='MID Term 1'!Q226+'MID Term 2'!N226 | I229: =IF((D229/$D$8)>=$I$8,1,0) | J229: =IF((E229/$E$8)>=$J$8,1,0) | K229: =IF((F229/$F$8)>=$K$8,1,0) | L229: =IF((G229/$G$8)>=$L$8,1,0) | M229: =IF((H229/$H$8)>=$M$8,1,0) | N229: =SUM(D229:H229) | O229: =ROUND(N229/2,0)
A230: 221 | B230: ='Sessional + End Term Assessment'!B265 | C230: ='Sessional + End Term Assessment'!C265 | D230: ='MID Term 1'!D227+'MID Term 2'!D227 | E230: ='MID Term 1'!H227+'MID Term 2'!E227 | F230: ='MID Term 1'!L227+'MID Term 2'!F227 | G230: ='MID Term 1'!P227+'MID Term 2'!J227 | H230: ='MID Term 1'!Q227+'MID Term 2'!N227 | I230: =IF((D230/$D$8)>=$I$8,1,0) | J230: =IF((E230/$E$8)>=$J$8,1,0) | K230: =IF((F230/$F$8)>=$K$8,1,0) | L230: =IF((G230/$G$8)>=$L$8,1,0) | M230: =IF((H230/$H$8)>=$M$8,1,0) | N230: =SUM(D230:H230) | O230: =ROUND(N230/2,0)
A231: 222 | B231: ='Sessional + End Term Assessment'!B266 | C231: ='Sessional + End Term Assessment'!C266 | D231: ='MID Term 1'!D228+'MID Term 2'!D228 | E231: ='MID Term 1'!H228+'MID Term 2'!E228 | F231: ='MID Term 1'!L228+'MID Term 2'!F228 | G231: ='MID Term 1'!P228+'MID Term 2'!J228 | H231: ='MID Term 1'!Q228+'MID Term 2'!N228 | I231: =IF((D231/$D$8)>=$I$8,1,0) | J231: =IF((E231/$E$8)>=$J$8,1,0) | K231: =IF((F231/$F$8)>=$K$8,1,0) | L231: =IF((G231/$G$8)>=$L$8,1,0) | M231: =IF((H231/$H$8)>=$M$8,1,0) | N231: =SUM(D231:H231) | O231: =ROUND(N231/2,0)
A232: 223 | B232: ='Sessional + End Term Assessment'!B267 | C232: ='Sessional + End Term Assessment'!C267 | D232: ='MID Term 1'!D229+'MID Term 2'!D229 | E232: ='MID Term 1'!H229+'MID Term 2'!E229 | F232: ='MID Term 1'!L229+'MID Term 2'!F229 | G232: ='MID Term 1'!P229+'MID Term 2'!J229 | H232: ='MID Term 1'!Q229+'MID Term 2'!N229 | I232: =IF((D232/$D$8)>=$I$8,1,0) | J232: =IF((E232/$E$8)>=$J$8,1,0) | K232: =IF((F232/$F$8)>=$K$8,1,0) | L232: =IF((G232/$G$8)>=$L$8,1,0) | M232: =IF((H232/$H$8)>=$M$8,1,0) | N232: =SUM(D232:H232) | O232: =ROUND(N232/2,0)
A233: 224 | B233: ='Sessional + End Term Assessment'!B268 | C233: ='Sessional + End Term Assessment'!C268 | D233: ='MID Term 1'!D230+'MID Term 2'!D230 | E233: ='MID Term 1'!H230+'MID Term 2'!E230 | F233: ='MID Term 1'!L230+'MID Term 2'!F230 | G233: ='MID Term 1'!P230+'MID Term 2'!J230 | H233: ='MID Term 1'!Q230+'MID Term 2'!N230 | I233: =IF((D233/$D$8)>=$I$8,1,0) | J233: =IF((E233/$E$8)>=$J$8,1,0) | K233: =IF((F233/$F$8)>=$K$8,1,0) | L233: =IF((G233/$G$8)>=$L$8,1,0) | M233: =IF((H233/$H$8)>=$M$8,1,0) | N233: =SUM(D233:H233) | O233: =ROUND(N233/2,0)
... A258: 249 | B258: ='Sessional + End Term Assessment'!B293 | C258: ='Sessional + End Term Assessment'!C293 | D258: ='MID Term 1'!D255+'MID Term 2'!D255 | E258: ='MID Term 1'!H255+'MID Term 2'!E255 | F258: ='MID Term 1'!L255+'MID Term 2'!F255 | G258: ='MID Term 1'!P255+'MID Term 2'!J255 | H258: ='MID Term 1'!Q255+'MID Term 2'!N255 | I258: =IF((D258/$D$8)>=$I$8,1,0) | J258: =IF((E258/$E$8)>=$J$8,1,0) | K258: =IF((F258/$F$8)>=$K$8,1,0) | L258: =IF((G258/$G$8)>=$L$8,1,0) | M258: =IF((H258/$H$8)>=$M$8,1,0) | N258: =SUM(D258:H258) | O258: =ROUND(N258/2,0)
C259: Total No. of Students | D259: 249 | E259: 249 | F259: 249 | G259: 249 | H259: 249 | I259: =SUM(I10:I258) | J259: =SUM(J10:J258) | K259: =SUM(K10:K258) | L259: =SUM(L10:L258) | M259: =SUM(M10:M258)
A260: Rationale: -While setting up the question paper choice was gIIIen within the same CO with same complexity/difficulty level and no CO is missed out. -If the student obtains target set for CO in terms of %age, score of 1 is gIIIen and if not zero is gIIIen -Those students who were found poor in achieving Course outcome, remedial classes are subjected to be scheduled.
A264: CO Attainment Calculation | D264: % of students get >= Target % | E264: CO Attainment Level
A265: No. of Students Attained CO23CS201.1 | D265: =ROUND((I259/D259*100),0) | E265: =IF(D265>100,"ERROR",IF(D265>=61,3,IF(D265>=46,2,IF(D265>=16,1,IF(D265>15,0,0))))) | F265: =E265*0.2
A266: No. of Students Attained CO23CS201.2 | D266: =ROUND((J259/E259*100),0) | E266: =IF(D266>100,"ERROR",IF(D266>=61,3,IF(D266>=46,2,IF(D266>=16,1,IF(D266>15,0,0))))) | F266: =E266*0.2 | H266: CO Achieved | J266: =SUM(F265:F269)
...

Sheet Attainment CO to PO Sessional
A1: ='CO-PO Mapping'!A1:P1
A2: CO to PO & PSO Attainment Through Sessional Assessment
A3: ='CO-PO Mapping'!A3:P3
A4: ='CO-PO Mapping'!A4:P4
A5: Course Outcome | B5: PO1 | C5: PO2 | D5: PO3 | E5: PO4 | F5: PO5 | G5: PO6 | H5: PO7 | I5: PO8 | J5: PO9 | K5: PO10 | L5: PO11 | M5: PO12 | N5: PSO1 | O5: PSO2 | P5: PSO3
A6: CO23CS201.1 | B6: ='Attainment Sheet Sessional'!E265*'CO-PO Mapping'!B6/3 | C6: ='Attainment Sheet Sessional'!E265*'CO-PO Mapping'!C6/3 | D6: ='Attainment Sheet Sessional'!$E265*'CO-PO Mapping'!D6/3 | E6: ='Attainment Sheet Sessional'!$E265*'CO-PO Mapping'!E6/3 | F6: ='Attainment Sheet Sessional'!$E265*'CO-PO Mapping'!F6/3 | G6: ='Attainment Sheet Sessional'!$E265*'CO-PO Mapping'!G6/3 | H6: ='Attainment Sheet Sessional'!$E265*'CO-PO Mapping'!H6/3 | I6: ='Attainment Sheet Sessional'!$E265*'CO-PO Mapping'!I6/3 | J6: ='Attainment Sheet Sessional'!$E265*'CO-PO Mapping'!J6/3 | K6: ='Attainment Sheet Sessional'!$E265*'CO-PO Mapping'!K6/3 | ... P6: ='Attainment Sheet Sessional'!$E265*'CO-PO Mapping'!P6/3
A7: CO23CS201.2 | B7: ='Attainment Sheet Sessional'!E266*'CO-PO Mapping'!B7/3 | C7: ='Attainment Sheet Sessional'!E266*'CO-PO Mapping'!C7/3 | D7: ='Attainment Sheet Sessional'!$E266*'CO-PO Mapping'!D7/3 | E7: ='Attainment Sheet Sessional'!$E266*'CO-PO Mapping'!E7/3 | F7: ='Attainment Sheet Sessional'!$E266*'CO-PO Mapping'!F7/3 | G7: ='Attainment Sheet Sessional'!$E266*'CO-PO Mapping'!G7/3 | H7: ='Attainment Sheet Sessional'!$E266*'CO-PO Mapping'!H7/3 | I7: ='Attainment Sheet Sessional'!$E266*'CO-PO Mapping'!I7/3 | J7: ='Attainment Sheet Sessional'!$E266*'CO-PO Mapping'!J7/3 | K7: ='Attainment Sheet Sessional'!$E266*'CO-PO Mapping'!K7/3 | ... P7: ='Attainment Sheet Sessional'!$E266*'CO-PO Mapping'!P7/3
A8: CO23CS201.3 | B8: ='Attainment Sheet Sessional'!E267*'CO-PO Mapping'!B8/3 | C8: ='Attainment Sheet Sessional'!E267*'CO-PO Mapping'!C8/3 | D8: ='Attainment Sheet Sessional'!$E267*'CO-PO Mapping'!D8/3 | E8: ='Attainment Sheet Sessional'!$E267*'CO-PO Mapping'!E8/3 | F8: ='Attainment Sheet Sessional'!$E267*'CO-PO Mapping'!F8/3 | G8: ='Attainment Sheet Sessional'!$E267*'CO-PO Mapping'!G8/3 | H8: ='Attainment Sheet Sessional'!$E267*'CO-PO Mapping'!H8/3 | I8: ='Attainment Sheet Sessional'!$E267*'CO-PO Mapping'!I8/3 | J8: ='Attainment Sheet Sessional'!$E267*'CO-PO Mapping'!J8/3 | K8: ='Attainment Sheet Sessional'!$E267*'CO-PO Mapping'!K8/3 | ... P8: ='Attainment Sheet Sessional'!$E267*'CO-PO Mapping'!P8/3
A9: CO23CS201.4 | B9: ='Attainment Sheet Sessional'!E268*'CO-PO Mapping'!B9/3 | C9: ='Attainment Sheet Sessional'!E268*'CO-PO Mapping'!C9/3 | D9: ='Attainment Sheet Sessional'!$E268*'CO-PO Mapping'!D9/3 | E9: ='Attainment Sheet Sessional'!$E268*'CO-PO Mapping'!E9/3 | F9: ='Attainment Sheet Sessional'!$E268*'CO-PO Mapping'!F9/3 | G9: ='Attainment Sheet Sessional'!$E268*'CO-PO Mapping'!G9/3 | H9: ='Attainment Sheet Sessional'!$E268*'CO-PO Mapping'!H9/3 | I9: ='Attainment Sheet Sessional'!$E268*'CO-PO Mapping'!I9/3 | J9: ='Attainment Sheet Sessional'!$E268*'CO-PO Mapping'!J9/3 | K9: ='Attainment Sheet Sessional'!$E268*'CO-PO Mapping'!K9/3 | ... P9: ='Attainment Sheet Sessional'!$E268*'CO-PO Mapping'!P9/3
A10: CO23CS201.5 | B10: ='Attainment Sheet Sessional'!E269*'CO-PO Mapping'!B10/3 | C10: ='Attainment Sheet Sessional'!E269*'CO-PO Mapping'!C10/3 | D10: ='Attainment Sheet Sessional'!$E269*'CO-PO Mapping'!D10/3 | E10: ='Attainment Sheet Sessional'!$E269*'CO-PO Mapping'!E10/3 | F10: ='Attainment Sheet Sessional'!$E269*'CO-PO Mapping'!F10/3 | G10: ='Attainment Sheet Sessional'!$E269*'CO-PO Mapping'!G10/3 | H10: ='Attainment Sheet Sessional'!$E269*'CO-PO Mapping'!H10/3 | I10: ='Attainment Sheet Sessional'!$E269*'CO-PO Mapping'!I10/3 | J10: ='Attainment Sheet Sessional'!$E269*'CO-PO Mapping'!J10/3 | K10: ='Attainment Sheet Sessional'!$E269*'CO-PO Mapping'!K10/3 | ... P10: ='Attainment Sheet Sessional'!$E269*'CO-PO Mapping'!P10/3
A11: ='CO-PO Mapping'!A11 | B11: =AVERAGE(B6:B10) | C11: =AVERAGE(C6:C10) | D11: =AVERAGE(D6:D10) | E11: =AVERAGE(E6:E10) | F11: =AVERAGE(F6:F10) | G11: =AVERAGE(G6:G10) | H11: =AVERAGE(H6:H10) | I11: =AVERAGE(I6:I10) | ... P11: =AVERAGE(P6:P10)
A12: Signature Subject Teacher

Sheet Attainment Tool C to PO FINAL
A1: ='CO-PO Mapping'!A1:P1
A2: Course to PO & PSO Attainment From All Tools
A3: ='CO-PO Mapping'!A3:P3
A4: ='CO-PO Mapping'!A4:P4
A5: Course | B5: PO1 | C5: PO2 | D5: PO3 | E5: PO4 | F5: PO5 | G5: PO6 | H5: PO7 | I5: PO8 | J5: PO9 | K5: PO10 | L5: PO11 | M5: PO12 | N5: PSO1 | O5: PSO2 | P5: PSO3
A6: CO12FY201 | B6: =AVERAGE('Attainment Tool 1 C to PO'!B6,'Attainment CO to PO Sessional'!B11) | C6: =AVERAGE('Attainment Tool 1 C to PO'!C6,'Attainment CO to PO Sessional'!C11) | D6: =AVERAGE('Attainment Tool 1 C to PO'!D6,'Attainment CO to PO Sessional'!D11) | E6: =AVERAGE('Attainment Tool 1 C to PO'!E6,'Attainment CO to PO Sessional'!E11) | F6: =AVERAGE('Attainment Tool 1 C to PO'!F6,'Attainment CO to PO Sessional'!F11) | G6: =AVERAGE('Attainment Tool 1 C to PO'!G6,'Attainment CO to PO Sessional'!G11) | H6: =AVERAGE('Attainment Tool 1 C to PO'!H6,'Attainment CO to PO Sessional'!H11) | I6: =AVERAGE('Attainment Tool 1 C to PO'!I6,'Attainment CO to PO Sessional'!I11) | ... P6: =AVERAGE('Attainment Tool 1 C to PO'!P6,'Attainment CO to PO Sessional'!P11)
A7: CO12FY201 (Round Off) | B7: =ROUND(B6,0) | C7: =ROUND(C6,0) | D7: =ROUND(D6,0) | E7: =ROUND(E6,0) | F7: =ROUND(F6,0) | G7: =ROUND(G6,0) | H7: =ROUND(H6,0) | I7: =ROUND(I6,0) | ... P7: =ROUND(P6,0)
A8: Signature Subject Teacher
